Workbook
Name CLIN: #REF!
Name Florin: #REF!
Name hi: #REF!
Name PHARM: #REF!
Name Pound: #REF!
Name swed: #REF!

Sheet (1) PROJECT STATEMENT
B2: PROJECT STATEMENT:
B3: Dear All:
B5: The objective of this project is to determine the "present value of cash flow earned per car" and provide recommendation to the management of your findings.
B6: The project and analysis is Excel Financial Modeling over the 7-year period.
B7: Once you get one " 5% Growth Model" completed, you can complete the other 3% and 8% quickly by duplicating and replacing the 5% with 3% and 8%, respectively.
B9: When knowing how much the organization earns in terms of PV cash profit per car, the management can set advertising budget and decide on how much to spend to advertise to draw new customers
B10: into its showroom for the first time.
B12: This project will teach you tremendously on Excel skills before entering the business workplace in Corporate America.
B14: Thank you.

Sheet (2) STATEMENT OF WORK
B2: Statement of Work
B4: Please describe in 1-3 short paragraphs and few bullets in between on what this work is all about.
B5: This is an introduction of your work to someone (e.g., other Department Managers within the Company) who have received your report, but have no other information about your work at all
B6: Simply write information about your work, it's business assumptions, it's financial & business importance, and how it would help the Marketing Managers make decision on the upcoming Advertising Programs.

Sheet (3)EXEC. SUMMARY&RECOMMENDATION
B1: Executive Summary and Recommendation
B3: Please describe the summary of your work in 1-3 short paragraphs and few bullets in between on your analysis and findings.
B4: This could be in the form of small "Contingency Table" summarizing your work with numbers.
C6: Analysis: 7-Year Model | E6: Economic Growth % | F6: Total Units Sold | G6: Total PV Cash Flow | H6: PV Cash Flow/Car
D7: Strong Economy | E7: 0.08
D8: Average Economy | E8: 0.05 | F8: ='(5) AnalysisModel-AverageGrowth'!B141 -> 16913899 | G8: ='(5) AnalysisModel-AverageGrowth'!B139 -> 3.2349686e+11 | H8: =G8/F8 -> 19126.096
D9: Poor Economy | E9: 0.03

Sheet (4) ANALYSIS ASSUMPTIONS
A2: PROJECT STATEMENT: | C2: According to the information provided below, it's required that you build a financial business model
C3: to determine the profit in terms of "Cash (PV) Profit Per Car Sold" for all the units sold over the next 6 years.
C4: Knowing the profit in terms of cash per car, the company can decide further on investing additional money in advertising.
C5: The company plan to offer a new model next year called Z5 with the ticket price of $83,500.
A6: KEY 1 | C6: Utilizing Regression Analytics, based on the same customer base, how many units expected to be sold annually.
C7: Determine the Correlation Coefficient between "Units Sold" vs. "Vehicle Price Per Unit"?
A8: FINANCIAL MODELING: | C8: You are only allowed to input the data for modeling purpose via Tab # 4 ……. Assumption Page!
C9: You are not allowed to input any data into Tab # 5 because all input data should be linked to Tab # 4, the feeding sheet.
C10: You are required to build 3 models based on 3 business scenarios - Good Economy, Poor Economy, and Average Economy.
A12: Analysis Assumptions: | B12: BMW U.S. Northeast Region Business Projection Fiscal 2022
B13: Units Sold | C13: Vehicle Sales Revenue Per Unit | D13: Vehicle Cost Per Unit | F13: Gross Profit Per Unit Sold
A14: Current Year - Units Sold | B14: =SUM(B16:B22) -> 2077362 | D14: 0.5
A16: BMW 1 Series | B16: 586000 | C16: 46000 | D16: =-C16*$D$14 -> -23000 | F16: =C16+D16 -> 23000
A17: 2 Series | B17: 458400 | C17: 49600 | D17: =-C17*$D$14 -> -24800 | F17: =C17+D17 -> 24800
A18: 3 Series | B18: 320000 | C18: 52000 | D18: =-C18*$D$14 -> -26000 | F18: =C18+D18 -> 26000
A19: 4 Series | B19: 258000 | C19: 56800 | D19: =-C19*$D$14 -> -28400 | F19: =C19+D19 -> 28400
A20: 5 Series | B20: 248000 | C20: 62500 | D20: =-C20*$D$14 -> -31250 | F20: =C20+D20 -> 31250
A21: 6 Series | B21: 120962 | C21: 72000 | D21: =-C21*$D$14 -> -36000 | F21: =C21+D21 -> 36000
A22: 7 Series | B22: 86000 | C22: 81500 | D22: =-C22*$D$14 -> -40750 | F22: =C22+D22 -> 40750
A24: Price Increase (Each Year) | B24: 0.0265
A25: Cost Increase (Each Year) | B25: 0.022
A27: Service and Parts Revenue per Car | B27: 7000
A28: Service and Parts amortized over | B28: 7 | C28: Years
A30: Annual Depreciation Expense | B30: -750000 | C30: ** The same amount every year
A31: Annual Interest Income/Expense | B31: -120000 | C31: ** The same amount every year
A32: G&A Expense Ratio | B32: -0.13 | C32: ** Assumed G&A Expense at the same % of revenue every year
A33: Discount Rate | B33: 0.06 | C33: ** Assumed at the same % every year
A34: ='(3)EXEC. SUMMARY&RECOMMENDATION'!D7 -> Strong Economy | B34: ='(3)EXEC. SUMMARY&RECOMMENDATION'!E7 -> 0.08
A35: ='(3)EXEC. SUMMARY&RECOMMENDATION'!D8 -> Average Economy | B35: ='(3)EXEC. SUMMARY&RECOMMENDATION'!E8 -> 0.05
A36: ='(3)EXEC. SUMMARY&RECOMMENDATION'!D9 -> Poor Economy | B36: ='(3)EXEC. SUMMARY&RECOMMENDATION'!E9 -> 0.03

Sheet (5) AnalysisModel-AverageGrowth
A1: BUSINESS SCENARIO - AVERAGE GROWTH | B1: ='(3)EXEC. SUMMARY&RECOMMENDATION'!E8 -> 0.05 | C1: AVERAGE GROWTH | G1: KEY
A2: Price Increase (Each Year) | B2: ='(4) ANALYSIS ASSUMPTIONS'!B24 -> 0.0265
A3: Cost Increase (Each Year) | B3: ='(4) ANALYSIS ASSUMPTIONS'!B25 -> 0.022
A5: Service and Parts Revenue per Car (7 Years) | B5: ='(4) ANALYSIS ASSUMPTIONS'!B27 -> 7000 | C5: Over the 7-Year Analysis Period
A6: Service and Parts annually allocated | B6: =B5/7 -> 1000
A8: Annual Depreciation Expense | B8: ='(4) ANALYSIS ASSUMPTIONS'!B30 -> -750000 | C8: Assumed Constant
A9: Annual Interest Income/Expense | B9: ='(4) ANALYSIS ASSUMPTIONS'!B31 -> -120000 | C9: Assumed Constant
A10: G&A Expense Ratio (% of Revenue) | B10: ='(4) ANALYSIS ASSUMPTIONS'!B32 -> -0.13
A11: Discount Rate | B11: ='(4) ANALYSIS ASSUMPTIONS'!B33 -> 0.06
A13: SEDANS
A14: Average Case Scenario (5% Growth) | B14: Year 0 | C14: Year 1 | D14: Year 2 | E14: Year 3 | F14: Year 4 | G14: Year 5 | H14: Year 6 | I14: 7 Year Total
A15: 1 Series Units Sold | B15: ='(4) ANALYSIS ASSUMPTIONS'!B16 -> 586000 | C15: =B15*(1+$B$1) -> 615300 | D15: =C15*(1+$B$1) -> 646065 | E15: =D15*(1+$B$1) -> 678368.25 | F15: =E15*(1+$B$1) -> 712286.66 | G15: =F15*(1+$B$1) -> 747901 | H15: =G15*(1+$B$1) -> 785296.05 | I15: =SUM(B15:H15) -> 4771217
A16: Selling Price | B16: ='(4) ANALYSIS ASSUMPTIONS'!C16 -> 46000 | C16: =B16*(1+$B$2) -> 47219 | D16: =C16*(1+$B$2) -> 48470.304 | E16: =D16*(1+$B$2) -> 49754.767 | F16: =E16*(1+$B$2) -> 51073.268 | G16: =F16*(1+$B$2) -> 52426.709 | H16: =G16*(1+$B$2) -> 53816.017 | I16: =SUM(B16:H16) -> 348760.06
A17: Revenues From Auto Sales | B17: =B16*B15 -> 26956000000 | C17: =C16*C15 -> 29053850700 | D17: =D16*D15 -> 3.1314967e+10 | E17: =E16*E15 -> 3.3752054e+10 | F17: =F16*F15 -> 3.6378808e+10 | G17: =G16*G15 -> 3.9209988e+10 | H17: =H16*H15 -> 4.2261506e+10 | I17: =SUM(B17:H17) -> 2.3892717e+11
A18: Profit from Service and Parts per Car | B18: =$B$6 -> 1000 | C18: =$B$6 -> 1000 | D18: =$B$6 -> 1000 | E18: =$B$6 -> 1000 | F18: =$B$6 -> 1000 | G18: =$B$6 -> 1000 | H18: =$B$6 -> 1000 | I18: =SUM(B18:H18) -> 7000
A19: Revenues From Auto Maintnence | B19: =B18*B15 -> 586000000 | C19: =C18*C15 -> 615300000 | D19: =D18*D15 -> 646065000 | E19: =E18*E15 -> 678368250 | F19: =F18*F15 -> 7.1228666e+08 | G19: =G18*G15 -> 7.47901e+08 | H19: =H18*H15 -> 7.8529605e+08 | I19: =SUM(B19:H19) -> 4.771217e+09
A20: Total Revenue | B20: =SUM(B19,B17) -> 27542000000 | C20: =SUM(C19,C17) -> 29669150700 | D20: =SUM(D19,D17) -> 3.1961032e+10 | E20: =SUM(E19,E17) -> 3.4430422e+10 | F20: =SUM(F19,F17) -> 3.7091094e+10 | G20: =SUM(G19,G17) -> 3.9957889e+10 | H20: =SUM(H19,H17) -> 4.3046802e+10 | I20: =SUM(B20:H20) -> 2.4369839e+11
A21: Cost to Build and Sell (50%) | B21: ='(4) ANALYSIS ASSUMPTIONS'!D16 -> -23000 | C21: =B21*(1+$B$3) -> -23506 | D21: =C21*(1+$B$3) -> -24023.132 | E21: =D21*(1+$B$3) -> -24551.641 | F21: =E21*(1+$B$3) -> -25091.777 | G21: =F21*(1+$B$3) -> -25643.796 | H21: =G21*(1+$B$3) -> -26207.96 | I21: =SUM(B21:H21) -> -172024.31
A22: Total Cost to Build and Sell | B22: =B21*B15 -> -13478000000 | C22: =C21*C15 -> -14463241800 | D22: =D21*D15 -> -1.5520505e+10 | E22: =E21*E15 -> -1.6655054e+10 | F22: =F21*F15 -> -1.7872538e+10 | G22: =G21*G15 -> -1.9179021e+10 | H22: =H21*H15 -> -2.0581007e+10 | I22: =SUM(B22:H22) -> -1.1774937e+11
A23: Gross Profit | B23: =SUM(B20,B22) -> 14064000000 | C23: =SUM(C20,C22) -> 15205908900 | D23: =SUM(D20,D22) -> 1.6440527e+10 | E23: =SUM(E20,E22) -> 1.7775368e+10 | F23: =SUM(F20,F22) -> 1.9218556e+10 | G23: =SUM(G20,G22) -> 2.0778869e+10 | H23: =SUM(H20,H22) -> 2.2465795e+10 | I23: =SUM(B23:H23) -> 1.2594902e+11
A24: G&A Expenses (13% of Revenue) | B24: =$B$10*B20 -> -3580460000 | C24: =$B$10*C20 -> -3856989591 | D24: =$B$10*D20 -> -4.1549341e+09 | E24: =$B$10*E20 -> -4.4759549e+09 | F24: =$B$10*F20 -> -4.8218422e+09 | G24: =$B$10*G20 -> -5.1945256e+09 | H24: =$B$10*H20 -> -5.5960842e+09 | I24: =SUM(B24:H24) -> -3.1680791e+10
A25: Depreciation and Amortization | B25: =$B$8 -> -750000 | C25: =$B$8 -> -750000 | D25: =$B$8 -> -750000 | E25: =$B$8 -> -750000 | F25: =$B$8 -> -750000 | G25: =$B$8 -> -750000 | H25: =$B$8 -> -750000 | I25: =SUM(B25:H25) -> -5250000
A26: Operating Income | B26: =B23+B24+B25 -> 10482790000 | C26: =C23+C24+C25 -> 11348169309 | D26: =D23+D24+D25 -> 1.2284843e+10 | E26: =E23+E24+E25 -> 1.3298664e+10 | F26: =F23+F24+F25 -> 1.4395964e+10 | G26: =G23+G24+G25 -> 1.5583593e+10 | H26: =H23+H24+H25 -> 1.686896e+10 | I26: =SUM(B26:H26) -> 9.4262983e+10
A27: Interest Income/(Expense) | B27: =$B$9 -> -120000 | C27: =$B$9 -> -120000 | D27: =$B$9 -> -120000 | E27: =$B$9 -> -120000 | F27: =$B$9 -> -120000 | G27: =$B$9 -> -120000 | H27: =$B$9 -> -120000 | I27: =SUM(B27:H27) -> -840000
A28: Net Income | B28: =B26+B27 -> 10482670000 | C28: =C26+C27 -> 11348049309 | D28: =D26+D27 -> 1.2284723e+10 | E28: =E26+E27 -> 1.3298544e+10 | F28: =F26+F27 -> 1.4395844e+10 | G28: =G26+G27 -> 1.5583473e+10 | H28: =H26+H27 -> 1.686884e+10 | I28: =SUM(B28:H28) -> 9.4262143e+10
A29: Total Profit from 1 Series Cars Sold | B29: =B28 -> 10482670000 | C29: =C28 -> 11348049309 | D29: =D28 -> 1.2284723e+10 | E29: =E28 -> 1.3298544e+10 | F29: =F28 -> 1.4395844e+10 | G29: =G28 -> 1.5583473e+10 | H29: =H28 -> 1.686884e+10 | I29: =SUM(B29:H29) -> 9.4262143e+10
A31: =A14 -> Average Case Scenario (5% Growth) | B31: Year 0 | C31: Year 1 | D31: Year 2 | E31: Year 3 | F31: Year 4 | G31: Year 5 | H31: Year 6 | I31: 7 Year Total
A32: 2 Series Units Sold | B32: ='(4) ANALYSIS ASSUMPTIONS'!B17 -> 458400 | C32: =B32*(1+$B$1) -> 481320 | D32: =C32*(1+$B$1) -> 505386 | E32: =D32*(1+$B$1) -> 530655.3 | F32: =E32*(1+$B$1) -> 557188.07 | G32: =F32*(1+$B$1) -> 585047.47 | H32: =G32*(1+$B$1) -> 614299.84 | I32: =SUM(B32:H32) -> 3732296.7
A33: Selling Price | B33: ='(4) ANALYSIS ASSUMPTIONS'!C17 -> 49600 | C33: =B33*(1+$B$2) -> 50914.4 | D33: =C33*(1+$B$2) -> 52263.632 | E33: =D33*(1+$B$2) -> 53648.618 | F33: =E33*(1+$B$2) -> 55070.306 | G33: =F33*(1+$B$2) -> 56529.669 | H33: =G33*(1+$B$2) -> 58027.706 | I33: =SUM(B33:H33) -> 376054.33
A34: Revenues From Auto Sales | B34: =B32*B33 -> 22736640000 | C34: =C32*C33 -> 24506119008 | D34: =D32*D33 -> 2.6413308e+10 | E34: =E32*E33 -> 2.8468923e+10 | F34: =F32*F33 -> 3.0684517e+10 | G34: =G32*G33 -> 3.307254e+10 | H34: =H32*H33 -> 3.564641e+10 | I34: =SUM(B34:H34) -> 2.0152846e+11
A35: Profit from Service and Parts per Car | B35: =$B$6 -> 1000 | C35: =$B$6 -> 1000 | D35: =$B$6 -> 1000 | E35: =$B$6 -> 1000 | F35: =$B$6 -> 1000 | G35: =$B$6 -> 1000 | H35: =$B$6 -> 1000 | I35: =SUM(B35:H35) -> 7000
A36: Revenues From Auto Maintnence | B36: =B35*B32 -> 458400000 | C36: =C35*C32 -> 481320000 | D36: =D35*D32 -> 505386000 | E36: =E35*E32 -> 5.306553e+08 | F36: =F35*F32 -> 5.5718807e+08 | G36: =G35*G32 -> 5.8504747e+08 | H36: =H35*H32 -> 6.1429984e+08 | I36: =SUM(B36:H36) -> 3.7322967e+09
A37: Total Revenue | B37: =B36+B34 -> 23195040000 | C37: =C36+C34 -> 24987439008 | D37: =D36+D34 -> 2.6918694e+10 | E37: =E36+E34 -> 2.8999579e+10 | F37: =F36+F34 -> 3.1241705e+10 | G37: =G36+G34 -> 3.3657587e+10 | H37: =H36+H34 -> 3.626071e+10 | I37: =SUM(B37:H37) -> 2.0526075e+11
A38: =A21 -> Cost to Build and Sell (50%) | B38: ='(4) ANALYSIS ASSUMPTIONS'!D17 -> -24800 | C38: =B38*(1+$B$3) -> -25345.6 | D38: =C38*(1+$B$3) -> -25903.203 | E38: =D38*(1+$B$3) -> -26473.074 | F38: =E38*(1+$B$3) -> -27055.481 | G38: =F38*(1+$B$3) -> -27650.702 | H38: =G38*(1+$B$3) -> -28259.017 | I38: =SUM(B38:H38) -> -185487.08
A39: Total Cost to Build and Sell | B39: =B38*B32 -> -11368320000 | C39: =C38*C32 -> -1.2199344e+10 | D39: =D38*D32 -> -1.3091116e+10 | E39: =E38*E32 -> -1.4048077e+10 | F39: =F38*F32 -> -1.5074991e+10 | G39: =G38*G32 -> -1.6176973e+10 | H39: =H38*H32 -> -1.735951e+10 | I39: =SUM(B39:H39) -> -9.9318332e+10
A40: Gross Profit | B40: =B37+B39 -> 11826720000 | C40: =C37+C39 -> 1.2788095e+10 | D40: =D37+D39 -> 1.3827577e+10 | E40: =E37+E39 -> 1.4951502e+10 | F40: =F37+F39 -> 1.6166714e+10 | G40: =G37+G39 -> 1.7480614e+10 | H40: =H37+H39 -> 1.89012e+10 | I40: =SUM(B40:H40) -> 1.0594242e+11
A41: =A24 -> G&A Expenses (13% of Revenue) | B41: =B37*$B$10 -> -3015355200 | C41: =C37*$B$10 -> -3.2483671e+09 | D41: =D37*$B$10 -> -3.4994302e+09 | E41: =E37*$B$10 -> -3.7699452e+09 | F41: =F37*$B$10 -> -4.0614217e+09 | G41: =G37*$B$10 -> -4.3754864e+09 | H41: =H37*$B$10 -> -4.7138923e+09 | I41: =SUM(B41:H41) -> -2.6683898e+10
A42: Depreciation and Amortization | B42: =$B$8 -> -750000 | C42: =$B$8 -> -750000 | D42: =$B$8 -> -750000 | E42: =$B$8 -> -750000 | F42: =$B$8 -> -750000 | G42: =$B$8 -> -750000 | H42: =$B$8 -> -750000 | I42: =SUM(B42:H42) -> -5250000
A43: Operating Income | B43: =B40+B41+B42 -> 8810614800 | C43: =C40+C41+C42 -> 9.5389777e+09 | D43: =D40+D41+D42 -> 1.0327397e+10 | E43: =E40+E41+E42 -> 1.1180807e+10 | F43: =F40+F41+F42 -> 1.2104542e+10 | G43: =G40+G41+G42 -> 1.3104378e+10 | H43: =H40+H41+H42 -> 1.4186558e+10 | I43: =SUM(B43:H43) -> 7.9253275e+10
A44: Interest Income | B44: =$B$9 -> -120000 | C44: =$B$9 -> -120000 | D44: =$B$9 -> -120000 | E44: =$B$9 -> -120000 | F44: =$B$9 -> -120000 | G44: =$B$9 -> -120000 | H44: =$B$9 -> -120000 | I44: =SUM(B44:H44) -> -840000
...

Sheet (6) Weak Economy

Sheet (7) Strong Economy
